WARNING:tensorflow:From C:\Users\flora\OneDrive\Documentos\MESTRADO_UFSC\rotinas\python\MESTRA\Lib\site-packages\keras\src\backend.py:873: The name tf.get_default_graph is deprecated. Please use tf.compat.v1.get_default_graph instead.
WARNING:tensorflow:From C:\Users\flora\OneDrive\Documentos\MESTRADO_UFSC\rotinas\python\MESTRA\Lib\site-packages\keras\src\optimizers\__init__.py:309: The name tf.train.Optimizer is deprecated. Please use tf.compat.v1.train.Optimizer instead.
[34m[1mwandb[39m[22m: [33mWARNING[39m The save_model argument by default saves the model in the HDF5 format that cannot save custom objects like subclassed models and custom layers. This behavior will be deprecated in a future release in favor of the SavedModel format. Meanwhile, the HDF5 model is saved as W&B files and the SavedModel as W&B Artifacts.
[34m[1mwandb[39m[22m: [33mWARNING[39m The data_type argument of wandb.keras.WandbCallback is deprecated and will be removed in a future release. Please use input_type instead.
[34m[1mwandb[39m[22m: [33mWARNING[39m Setting input_type = data_type.
Epoch 1/10
Traceback (most recent call last):
  File "C:\Users\flora\OneDrive\Documentos\MESTRADO_UFSC\rotinas\python\ml-class\my_data\mlp_mydata.py", line 112, in <module>
    model.fit(x_train_normalized, y_train, validation_data=(x_test_normalized, y_test),
  File "C:\Users\flora\OneDrive\Documentos\MESTRADO_UFSC\rotinas\python\MESTRA\Lib\site-packages\keras\src\utils\traceback_utils.py", line 70, in error_handler
    raise e.with_traceback(filtered_tb) from None
  File "C:\Users\flora\AppData\Local\Temp\__autograph_generated_filet55vp8xz.py", line 18, in tf__train_function
    raise
ValueError: in user code:
    File "C:\Users\flora\OneDrive\Documentos\MESTRADO_UFSC\rotinas\python\MESTRA\Lib\site-packages\keras\src\engine\training.py", line 1401, in train_function  *
        return step_function(self, iterator)
    File "C:\Users\flora\OneDrive\Documentos\MESTRADO_UFSC\rotinas\python\MESTRA\Lib\site-packages\keras\src\engine\training.py", line 1384, in step_function  **
        outputs = model.distribute_strategy.run(run_step, args=(data,))
    File "C:\Users\flora\OneDrive\Documentos\MESTRADO_UFSC\rotinas\python\MESTRA\Lib\site-packages\keras\src\engine\training.py", line 1373, in run_step  **
        outputs = model.train_step(data)
    File "C:\Users\flora\OneDrive\Documentos\MESTRADO_UFSC\rotinas\python\MESTRA\Lib\site-packages\keras\src\engine\training.py", line 1150, in train_step
        y_pred = self(x, training=True)
    File "C:\Users\flora\OneDrive\Documentos\MESTRADO_UFSC\rotinas\python\MESTRA\Lib\site-packages\keras\src\utils\traceback_utils.py", line 70, in error_handler
        raise e.with_traceback(filtered_tb) from None
    File "C:\Users\flora\OneDrive\Documentos\MESTRADO_UFSC\rotinas\python\MESTRA\Lib\site-packages\keras\src\engine\input_spec.py", line 280, in assert_input_compatibility
        raise ValueError(
    ValueError: Exception encountered when calling layer 'sequential' (type Sequential).
    Input 0 of layer "dense" is incompatible with the layer: expected axis -1 of input shape to have value 37636, but received input with shape (None, 112908)
    Call arguments received by layer 'sequential' (type Sequential):
      â€¢ inputs=tf.Tensor(shape=(None, 194, 194, 3), dtype=float32)
      â€¢ training=True
      â€¢ mask=None